Internal Server Error: /api/compras/
Traceback (most recent call last):
  File "C:\Users\FLAVIA ALEGRO AOKI\AppData\Local\Programs\Python\Python312\Lib\site-packages\django\core\handlers\exception.py", line 55, in inner
    response = get_response(request)
               ^^^^^^^^^^^^^^^^^^^^^
  File "C:\Users\FLAVIA ALEGRO AOKI\AppData\Local\Programs\Python\Python312\Lib\site-packages\django\core\handlers\base.py", line 197, in _get_response
    response = wrapped_callback(request, *callback_args, **callback_kwargs)
               ^^^^^^^^^^^^^^^^^^^^^^^^^^^^^^^^^^^^^^^^^^^^^^^^^^^^^^^^^^^^
  File "C:\Users\FLAVIA ALEGRO AOKI\AppData\Local\Programs\Python\Python312\Lib\site-packages\django\views\decorators\csrf.py", line 65, in _view_wrapper
    return view_func(request, *args, **kwargs)
           ^^^^^^^^^^^^^^^^^^^^^^^^^^^^^^^^^^^
  File "C:\Users\FLAVIA ALEGRO AOKI\AppData\Local\Programs\Python\Python312\Lib\site-packages\rest_framework\viewsets.py", line 125, in view
    return self.dispatch(request, *args, **kwargs)
           ^^^^^^^^^^^^^^^^^^^^^^^^^^^^^^^^^^^^^^^
  File "C:\Users\FLAVIA ALEGRO AOKI\AppData\Local\Programs\Python\Python312\Lib\site-packages\rest_framework\views.py", line 515, in dispatch
    response = self.handle_exception(exc)
               ^^^^^^^^^^^^^^^^^^^^^^^^^^
  File "C:\Users\FLAVIA ALEGRO AOKI\AppData\Local\Programs\Python\Python312\Lib\site-packages\rest_framework\views.py", line 475, in handle_exception
    self.raise_uncaught_exception(exc)
  File "C:\Users\FLAVIA ALEGRO AOKI\AppData\Local\Programs\Python\Python312\Lib\site-packages\rest_framework\views.py", line 486, in raise_uncaught_exception
    raise exc
  File "C:\Users\FLAVIA ALEGRO AOKI\AppData\Local\Programs\Python\Python312\Lib\site-packages\rest_framework\views.py", line 512, in dispatch
    response = handler(request, *args, **kwargs)
               ^^^^^^^^^^^^^^^^^^^^^^^^^^^^^^^^^
  File "C:\Users\FLAVIA ALEGRO AOKI\AppData\Local\Programs\Python\Python312\Lib\site-packages\rest_framework\mixins.py", line 43, in list
    return self.get_paginated_response(serializer.data)
                                       ^^^^^^^^^^^^^^^
  File "C:\Users\FLAVIA ALEGRO AOKI\AppData\Local\Programs\Python\Python312\Lib\site-packages\rest_framework\serializers.py", line 797, in data
    ret = super().data
          ^^^^^^^^^^^^
  File "C:\Users\FLAVIA ALEGRO AOKI\AppData\Local\Programs\Python\Python312\Lib\site-packages\rest_framework\serializers.py", line 251, in data
    self._data = self.to_representation(self.instance)
                 ^^^^^^^^^^^^^^^^^^^^^^^^^^^^^^^^^^^^^
  File "C:\Users\FLAVIA ALEGRO AOKI\AppData\Local\Programs\Python\Python312\Lib\site-packages\rest_framework\serializers.py", line 716, in to_representation
    self.child.to_representation(item) for item in iterable
    ^^^^^^^^^^^^^^^^^^^^^^^^^^^^^^^^^^
  File "C:\Users\FLAVIA ALEGRO AOKI\benjamim-2\backend\core\serializers.py", line 542, in to_representation
    representation = super().to_representation(instance)
                     ^^^^^^^^^^^^^^^^^^^^^^^^^^^^^^^^^^^
  File "C:\Users\FLAVIA ALEGRO AOKI\AppData\Local\Programs\Python\Python312\Lib\site-packages\rest_framework\serializers.py", line 540, in to_representation
    ret[field.field_name] = field.to_representation(attribute)
                            ^^^^^^^^^^^^^^^^^^^^^^^^^^^^^^^^^^
  File "C:\Users\FLAVIA ALEGRO AOKI\AppData\Local\Programs\Python\Python312\Lib\site-packages\rest_framework\serializers.py", line 716, in to_representation
    self.child.to_representation(item) for item in iterable
    ^^^^^^^^^^^^^^^^^^^^^^^^^^^^^^^^^^
  File "C:\Users\FLAVIA ALEGRO AOKI\AppData\Local\Programs\Python\Python312\Lib\site-packages\rest_framework\serializers.py", line 540, in to_representation
    ret[field.field_name] = field.to_representation(attribute)
                            ^^^^^^^^^^^^^^^^^^^^^^^^^^^^^^^^^^
  File "C:\Users\FLAVIA ALEGRO AOKI\AppData\Local\Programs\Python\Python312\Lib\site-packages\rest_framework\fields.py", line 1870, in to_representation
    return method(value)
           ^^^^^^^^^^^^^
  File "C:\Users\FLAVIA ALEGRO AOKI\benjamim-2\backend\core\serializers.py", line 458, in get_arquivo_tamanho
    return obj.arquivo.size
           ^^^^^^^^^^^^^^^^
  File "C:\Users\FLAVIA ALEGRO AOKI\AppData\Local\Programs\Python\Python312\Lib\site-packages\django\db\models\fields\files.py", line 77, in size
    return self.storage.size(self.name)
           ^^^^^^^^^^^^^^^^^^^^^^^^^^^^
  File "C:\Users\FLAVIA ALEGRO AOKI\AppData\Local\Programs\Python\Python312\Lib\site-packages\django\core\files\storage\filesystem.py", line 223, in size
    return os.path.getsize(self.path(name))
           ^^^^^^^^^^^^^^^^^^^^^^^^^^^^^^^^
  File "<frozen genericpath>", line 62, in getsize
FileNotFoundError: [WinError 3] O sistema não pode encontrar o caminho especificado: 'C:\\Users\\FLAVIA ALEGRO AOKI\\benjamim-2\\backend\\media\\anexos\\compras\\7\\fundo.jpg'
Internal Server Error: /api/compras/
Traceback (most recent call last):
  File "C:\Users\FLAVIA ALEGRO AOKI\AppData\Local\Programs\Python\Python312\Lib\site-packages\django\core\handlers\exception.py", line 55, in inner
    response = get_response(request)
               ^^^^^^^^^^^^^^^^^^^^^
  File "C:\Users\FLAVIA ALEGRO AOKI\AppData\Local\Programs\Python\Python312\Lib\site-packages\django\core\handlers\base.py", line 197, in _get_response
    response = wrapped_callback(request, *callback_args, **callback_kwargs)
               ^^^^^^^^^^^^^^^^^^^^^^^^^^^^^^^^^^^^^^^^^^^^^^^^^^^^^^^^^^^^
  File "C:\Users\FLAVIA ALEGRO AOKI\AppData\Local\Programs\Python\Python312\Lib\site-packages\django\views\decorators\csrf.py", line 65, in _view_wrapper
    return view_func(request, *args, **kwargs)
           ^^^^^^^^^^^^^^^^^^^^^^^^^^^^^^^^^^^
  File "C:\Users\FLAVIA ALEGRO AOKI\AppData\Local\Programs\Python\Python312\Lib\site-packages\rest_framework\viewsets.py", line 125, in view
    return self.dispatch(request, *args, **kwargs)
           ^^^^^^^^^^^^^^^^^^^^^^^^^^^^^^^^^^^^^^^
  File "C:\Users\FLAVIA ALEGRO AOKI\AppData\Local\Programs\Python\Python312\Lib\site-packages\rest_framework\views.py", line 515, in dispatch
    response = self.handle_exception(exc)
               ^^^^^^^^^^^^^^^^^^^^^^^^^^
  File "C:\Users\FLAVIA ALEGRO AOKI\AppData\Local\Programs\Python\Python312\Lib\site-packages\rest_framework\views.py", line 475, in handle_exception
    self.raise_uncaught_exception(exc)
  File "C:\Users\FLAVIA ALEGRO AOKI\AppData\Local\Programs\Python\Python312\Lib\site-packages\rest_framework\views.py", line 486, in raise_uncaught_exception
    raise exc
  File "C:\Users\FLAVIA ALEGRO AOKI\AppData\Local\Programs\Python\Python312\Lib\site-packages\rest_framework\views.py", line 512, in dispatch
    response = handler(request, *args, **kwargs)
               ^^^^^^^^^^^^^^^^^^^^^^^^^^^^^^^^^
  File "C:\Users\FLAVIA ALEGRO AOKI\AppData\Local\Programs\Python\Python312\Lib\site-packages\rest_framework\mixins.py", line 43, in list
    return self.get_paginated_response(serializer.data)
                                       ^^^^^^^^^^^^^^^
  File "C:\Users\FLAVIA ALEGRO AOKI\AppData\Local\Programs\Python\Python312\Lib\site-packages\rest_framework\serializers.py", line 797, in data
    ret = super().data
          ^^^^^^^^^^^^
  File "C:\Users\FLAVIA ALEGRO AOKI\AppData\Local\Programs\Python\Python312\Lib\site-packages\rest_framework\serializers.py", line 251, in data
    self._data = self.to_representation(self.instance)
                 ^^^^^^^^^^^^^^^^^^^^^^^^^^^^^^^^^^^^^
  File "C:\Users\FLAVIA ALEGRO AOKI\AppData\Local\Programs\Python\Python312\Lib\site-packages\rest_framework\serializers.py", line 716, in to_representation
    self.child.to_representation(item) for item in iterable
    ^^^^^^^^^^^^^^^^^^^^^^^^^^^^^^^^^^
  File "C:\Users\FLAVIA ALEGRO AOKI\benjamim-2\backend\core\serializers.py", line 542, in to_representation
    representation = super().to_representation(instance)
                     ^^^^^^^^^^^^^^^^^^^^^^^^^^^^^^^^^^^
  File "C:\Users\FLAVIA ALEGRO AOKI\AppData\Local\Programs\Python\Python312\Lib\site-packages\rest_framework\serializers.py", line 540, in to_representation
    ret[field.field_name] = field.to_representation(attribute)
                            ^^^^^^^^^^^^^^^^^^^^^^^^^^^^^^^^^^
  File "C:\Users\FLAVIA ALEGRO AOKI\AppData\Local\Programs\Python\Python312\Lib\site-packages\rest_framework\serializers.py", line 716, in to_representation
    self.child.to_representation(item) for item in iterable
    ^^^^^^^^^^^^^^^^^^^^^^^^^^^^^^^^^^
  File "C:\Users\FLAVIA ALEGRO AOKI\AppData\Local\Programs\Python\Python312\Lib\site-packages\rest_framework\serializers.py", line 540, in to_representation
    ret[field.field_name] = field.to_representation(attribute)
                            ^^^^^^^^^^^^^^^^^^^^^^^^^^^^^^^^^^
  File "C:\Users\FLAVIA ALEGRO AOKI\AppData\Local\Programs\Python\Python312\Lib\site-packages\rest_framework\fields.py", line 1870, in to_representation
    return method(value)
           ^^^^^^^^^^^^^
  File "C:\Users\FLAVIA ALEGRO AOKI\benjamim-2\backend\core\serializers.py", line 458, in get_arquivo_tamanho
    return obj.arquivo.size
           ^^^^^^^^^^^^^^^^
  File "C:\Users\FLAVIA ALEGRO AOKI\AppData\Local\Programs\Python\Python312\Lib\site-packages\django\db\models\fields\files.py", line 77, in size
    return self.storage.size(self.name)
           ^^^^^^^^^^^^^^^^^^^^^^^^^^^^
  File "C:\Users\FLAVIA ALEGRO AOKI\AppData\Local\Programs\Python\Python312\Lib\site-packages\django\core\files\storage\filesystem.py", line 223, in size
    return os.path.getsize(self.path(name))
           ^^^^^^^^^^^^^^^^^^^^^^^^^^^^^^^^
  File "<frozen genericpath>", line 62, in getsize
FileNotFoundError: [WinError 3] O sistema não pode encontrar o caminho especificado: 'C:\\Users\\FLAVIA ALEGRO AOKI\\benjamim-2\\backend\\media\\anexos\\compras\\7\\fundo.jpg'
"GET /api/compras/?page=1 HTTP/1.1" 500 180872